2025-04-09 00:57:08,872 ERROR: Exception on /shipments/ [GET] [in C:\temp\shipping_app\venv\Lib\site-packages\flask\app.py:1414]
Traceback (most recent call last):
  File "C:\temp\shipping_app\venv\Lib\site-packages\sqlalchemy\engine\base.py", line 1964, in _exec_single_context
    self.dialect.do_execute(
  File "C:\temp\shipping_app\venv\Lib\site-packages\sqlalchemy\engine\default.py", line 942, in do_execute
    cursor.execute(statement, parameters)
  File "C:\temp\shipping_app\venv\Lib\site-packages\pymysql\cursors.py", line 153, in execute
    result = self._query(query)
             ^^^^^^^^^^^^^^^^^^
  File "C:\temp\shipping_app\venv\Lib\site-packages\pymysql\cursors.py", line 322, in _query
    conn.query(q)
  File "C:\temp\shipping_app\venv\Lib\site-packages\pymysql\connections.py", line 558, in query
    self._affected_rows = self._read_query_result(unbuffered=unbuffered)
                          ^^^^^^^^^^^^^^^^^^^^^^^^^^^^^^^^^^^^^^^^^^^^^^
  File "C:\temp\shipping_app\venv\Lib\site-packages\pymysql\connections.py", line 822, in _read_query_result
    result.read()
  File "C:\temp\shipping_app\venv\Lib\site-packages\pymysql\connections.py", line 1200, in read
    first_packet = self.connection._read_packet()
                   ^^^^^^^^^^^^^^^^^^^^^^^^^^^^^^
  File "C:\temp\shipping_app\venv\Lib\site-packages\pymysql\connections.py", line 772, in _read_packet
    packet.raise_for_error()
  File "C:\temp\shipping_app\venv\Lib\site-packages\pymysql\protocol.py", line 221, in raise_for_error
    err.raise_mysql_exception(self._data)
  File "C:\temp\shipping_app\venv\Lib\site-packages\pymysql\err.py", line 143, in raise_mysql_exception
    raise errorclass(errno, errval)
pymysql.err.OperationalError: (1054, "Unknown column 'shipment.status' in 'field list'")

The above exception was the direct cause of the following exception:

Traceback (most recent call last):
  File "C:\temp\shipping_app\venv\Lib\site-packages\flask\app.py", line 2190, in wsgi_app
    response = self.full_dispatch_request()
               ^^^^^^^^^^^^^^^^^^^^^^^^^^^^
  File "C:\temp\shipping_app\venv\Lib\site-packages\flask\app.py", line 1486, in full_dispatch_request
    rv = self.handle_user_exception(e)
         ^^^^^^^^^^^^^^^^^^^^^^^^^^^^^
  File "C:\temp\shipping_app\venv\Lib\site-packages\flask\app.py", line 1484, in full_dispatch_request
    rv = self.dispatch_request()
         ^^^^^^^^^^^^^^^^^^^^^^^
  File "C:\temp\shipping_app\venv\Lib\site-packages\flask\app.py", line 1469, in dispatch_request
    return self.ensure_sync(self.view_functions[rule.endpoint])(**view_args)
           ^^^^^^^^^^^^^^^^^^^^^^^^^^^^^^^^^^^^^^^^^^^^^^^^^^^^^^^^^^^^^^^^^
  File "C:\temp\shipping_app\venv\Lib\site-packages\flask_login\utils.py", line 290, in decorated_view
    return current_app.ensure_sync(func)(*args, **kwargs)
           ^^^^^^^^^^^^^^^^^^^^^^^^^^^^^^^^^^^^^^^^^^^^^^
  File "C:\temp\shipping_app\app\shipments\routes.py", line 27, in list_shipments
    shipments = query.order_by(Shipment.created_at.desc()).paginate(
                ^^^^^^^^^^^^^^^^^^^^^^^^^^^^^^^^^^^^^^^^^^^^^^^^^^^^
  File "C:\temp\shipping_app\venv\Lib\site-packages\flask_sqlalchemy\query.py", line 98, in paginate
    return QueryPagination(
           ^^^^^^^^^^^^^^^^
  File "C:\temp\shipping_app\venv\Lib\site-packages\flask_sqlalchemy\pagination.py", line 72, in __init__
    items = self._query_items()
            ^^^^^^^^^^^^^^^^^^^
  File "C:\temp\shipping_app\venv\Lib\site-packages\flask_sqlalchemy\pagination.py", line 358, in _query_items
    out = query.limit(self.per_page).offset(self._query_offset).all()
          ^^^^^^^^^^^^^^^^^^^^^^^^^^^^^^^^^^^^^^^^^^^^^^^^^^^^^^^^^^^
  File "C:\temp\shipping_app\venv\Lib\site-packages\sqlalchemy\orm\query.py", line 2704, in all
    return self._iter().all()  # type: ignore
           ^^^^^^^^^^^^
  File "C:\temp\shipping_app\venv\Lib\site-packages\sqlalchemy\orm\query.py", line 2858, in _iter
    result: Union[ScalarResult[_T], Result[_T]] = self.session.execute(
                                                  ^^^^^^^^^^^^^^^^^^^^^
  File "C:\temp\shipping_app\venv\Lib\site-packages\sqlalchemy\orm\session.py", line 2365, in execute
    return self._execute_internal(
           ^^^^^^^^^^^^^^^^^^^^^^^
  File "C:\temp\shipping_app\venv\Lib\site-packages\sqlalchemy\orm\session.py", line 2251, in _execute_internal
    result: Result[Any] = compile_state_cls.orm_execute_statement(
                          ^^^^^^^^^^^^^^^^^^^^^^^^^^^^^^^^^^^^^^^^
  File "C:\temp\shipping_app\venv\Lib\site-packages\sqlalchemy\orm\context.py", line 306, in orm_execute_statement
    result = conn.execute(
             ^^^^^^^^^^^^^
  File "C:\temp\shipping_app\venv\Lib\site-packages\sqlalchemy\engine\base.py", line 1416, in execute
    return meth(
           ^^^^^
  File "C:\temp\shipping_app\venv\Lib\site-packages\sqlalchemy\sql\elements.py", line 523, in _execute_on_connection
    return connection._execute_clauseelement(
           ^^^^^^^^^^^^^^^^^^^^^^^^^^^^^^^^^^
  File "C:\temp\shipping_app\venv\Lib\site-packages\sqlalchemy\engine\base.py", line 1638, in _execute_clauseelement
    ret = self._execute_context(
          ^^^^^^^^^^^^^^^^^^^^^^
  File "C:\temp\shipping_app\venv\Lib\site-packages\sqlalchemy\engine\base.py", line 1843, in _execute_context
    return self._exec_single_context(
           ^^^^^^^^^^^^^^^^^^^^^^^^^^
  File "C:\temp\shipping_app\venv\Lib\site-packages\sqlalchemy\engine\base.py", line 1983, in _exec_single_context
    self._handle_dbapi_exception(
  File "C:\temp\shipping_app\venv\Lib\site-packages\sqlalchemy\engine\base.py", line 2352, in _handle_dbapi_exception
    raise sqlalchemy_exception.with_traceback(exc_info[2]) from e
  File "C:\temp\shipping_app\venv\Lib\site-packages\sqlalchemy\engine\base.py", line 1964, in _exec_single_context
    self.dialect.do_execute(
  File "C:\temp\shipping_app\venv\Lib\site-packages\sqlalchemy\engine\default.py", line 942, in do_execute
    cursor.execute(statement, parameters)
  File "C:\temp\shipping_app\venv\Lib\site-packages\pymysql\cursors.py", line 153, in execute
    result = self._query(query)
             ^^^^^^^^^^^^^^^^^^
  File "C:\temp\shipping_app\venv\Lib\site-packages\pymysql\cursors.py", line 322, in _query
    conn.query(q)
  File "C:\temp\shipping_app\venv\Lib\site-packages\pymysql\connections.py", line 558, in query
    self._affected_rows = self._read_query_result(unbuffered=unbuffered)
                          ^^^^^^^^^^^^^^^^^^^^^^^^^^^^^^^^^^^^^^^^^^^^^^
  File "C:\temp\shipping_app\venv\Lib\site-packages\pymysql\connections.py", line 822, in _read_query_result
    result.read()
  File "C:\temp\shipping_app\venv\Lib\site-packages\pymysql\connections.py", line 1200, in read
    first_packet = self.connection._read_packet()
                   ^^^^^^^^^^^^^^^^^^^^^^^^^^^^^^
  File "C:\temp\shipping_app\venv\Lib\site-packages\pymysql\connections.py", line 772, in _read_packet
    packet.raise_for_error()
  File "C:\temp\shipping_app\venv\Lib\site-packages\pymysql\protocol.py", line 221, in raise_for_error
    err.raise_mysql_exception(self._data)
  File "C:\temp\shipping_app\venv\Lib\site-packages\pymysql\err.py", line 143, in raise_mysql_exception
    raise errorclass(errno, errval)
sqlalchemy.exc.OperationalError: (pymysql.err.OperationalError) (1054, "Unknown column 'shipment.status' in 'field list'")
[SQL: SELECT shipment.id AS shipment_id, shipment.sender_id AS shipment_sender_id, shipment.recipient_id AS shipment_recipient_id, shipment.carrier_id AS shipment_carrier_id, shipment.sender_name AS shipment_sender_name, shipment.sender_phone AS shipment_sender_phone, shipment.sender_address AS shipment_sender_address, shipment.recipient_name AS shipment_recipient_name, shipment.recipient_phone AS shipment_recipient_phone, shipment.recipient_address AS shipment_recipient_address, shipment.destination_city AS shipment_destination_city, shipment.carrier_name AS shipment_carrier_name, shipment.carrier_phone AS shipment_carrier_phone, shipment.package_count AS shipment_package_count, shipment.weight_kg AS shipment_weight_kg, shipment.price AS shipment_price, shipment.notes AS shipment_notes, shipment.status AS shipment_status, shipment.created_at AS shipment_created_at, shipment.user_id AS shipment_user_id 
FROM shipment ORDER BY shipment.created_at DESC 
 LIMIT %(param_1)s, %(param_2)s]
[parameters: {'param_1': 0, 'param_2': 10}]
(Background on this error at: https://sqlalche.me/e/20/e3q8)
2025-04-09 01:01:48,972 INFO: Shipping App startup [in C:\temp\shipping_app\app\__init__.py:56]
